Workbook

Sheet 📦 Productos
A1: 📦 MARYBE — Exportación de Productos (28/7/2026)
A2: ⚠ Exportación generada el 28/7/2026, 04:37:08 — 597 productos. Las columnas Sección, Categoría, Subcategoría y Tipo tienen listas desplegables en cascada.
A3: ID Original * | B3: SKU / EAN | C3: Nombre * | D3: Marca | E3: Sección * | F3: Categoría | G3: Subcategoría | H3: Tipo | I3: Descripción | J3: Especificaciones | K3: Proveedor | L3: Publicado | M3: Destacado | N3: Stock | O3: Características | P3: Precio * | Q3: Precio Oferta | R3: % Descuento 🔒
A4: 4752 | B4: 3274872495852 | C4: KENZO INDIGO POUR HOMME EDP | D4: Kenzo | E4: Perfumería | F4: Fragancias | G4: Fragancias | I4: KENZO INDIGO POUR HOMME EDP | J4: Inspirado en las tradiciones japonesas, en particular el teñido indigo. Encarna el encuentro entre la sensualidad del iris, la vivacidad del acorde marino y la calidez del cuero. Creada por Quentin Bisch, esta fragancia te transporta a costas inexploradas. Reinventa el acorde marino característico de la gama, añadiendo un corazón de iris con facetas cremosas, amaderadas y almizcladas, tan seductor como el aroma de la piel que emerge del agua. En la base, un acorde de cuero con acentos casi ahumados refuerza la sensualidad del aroma con el poder de la madera de Akigala y el sándalo. | L4: NO | M4: SI | N4: 0 | O4: Prueba | Test | SeSubeAsí | R4: =IF(AND(P4>0,Q4>0),ROUND((1-Q4/P4)*100,0),0) -> 0
A5: 4754 | B5: 3274872357129 | C5: KENZO AQUA FEMME EDT | D5: Kenzo | E5: Perfumería | F5: Fragancias | G5: Hombre | I5: KENZO AQUA FEMME EDT | J5: Notas de salida: Hojas de frambuesa, mandarina y limón. | L5: NO | M5: SI | N5: 0 | R5: =IF(AND(P5>0,Q5>0),ROUND((1-Q5/P5)*100,0),0) -> 0
A6: 4755 | B6: 3274872357228 | C6: KENZO AQUA HOMME EDT | D6: Kenzo | E6: Perfumería | F6: Fragancias | G6: Hombre | I6: KENZO AQUA HOMME EDT | J6: Fragancia de la familia olfativa Aromática Acuática . Se lanzó en 2018. Creada por Ane Ayo y Philippe Romano. Notas de Salida : manzana, pimienta rosa y bergamota; Notas de Corazón : avellana, notas acuáticas, notas verdes y sésamo (ajonjolí); Notas de Fondo: haba tonka, sándalo, cedro, vainilla, ámbar y almizcle. | L6: NO | M6: SI | N6: 0 | R6: =IF(AND(P6>0,Q6>0),ROUND((1-Q6/P6)*100,0),0) -> 0
A7: 4756 | B7: 3274872430587 | C7: KENZO D ETE | D7: Kenzo | E7: Perfumería | F7: Fragancias | G7: Hombre | I7: KENZO D ETE | J7: Familia olfativa Floral Verde. Se lanzó en 2002. La Nariz detrás de esta fragrancia es Antoine Lie. Notas de Salida : lirio de los valles (muguete) y notas verdes; Notas de Corazón : jacinto, jazmín y peonía; Notas de Fondo :almizcle blanco y sándalo. | L7: NO | M7: SI | N7: 0 | R7: =IF(AND(P7>0,Q7>0),ROUND((1-Q7/P7)*100,0),0) -> 38
A8: 4757 | B8: 3274872406216 | C8: KENZO FLOWER POPPY BOUQUET EDP | D8: Kenzo | E8: Perfumería | F8: Fragancias | G8: Hombre | I8: KENZO FLOWER POPPY BOUQUET EDP | J8: Familia olfativa Floral Se lanzó en 2020. Creada por Dora Baghriche y Alberto Morillas. Nota de Salida : Pera Nashi; Notas de Corazón :gardenia y rosa de Bulgaria (rosa Damascena de Bulgaria); Nota de Fondo : árbol del almendro. | L8: NO | M8: SI | N8: 0 | R8: =IF(AND(P8>0,Q8>0),ROUND((1-Q8/P8)*100,0),0) -> 26
A9: 4758 | B9: 3274872439603 | C9: KENZO FLOWER POPPY BOUQUET EDT | D9: Kenzo | E9: Perfumería | F9: Fragancias | G9: Hombre | I9: KENZO FLOWER POPPY BOUQUET EDT | J9: Una expresión joven, colorida y pop de la amapola emblemática, que se adorna con notas refrescantes y citricas. Un auténtico jugo que florece espontáneamente sobre la piel, como un bouquet de múltiples colores. Evoca un auténtico momento de felicidad. Una fusión donde la Almendra Verde y las Hojas de Té se despiertan con un trazo de Esencia de Mandarina. En corazón, encontramos una auténtica invasión floral de Jazmín Sambac, Gardenia Golden y Rosa Damascena. Por último, notas amaderadas de Pachulí y Cedro de Virginia, asociadas a Almizcles Blancos, firman este perfume de la sensualidad natural FLOWER BY KENZO. | L9: NO | M9: SI | N9: 0 | R9: =IF(AND(P9>0,Q9>0),ROUND((1-Q9/P9)*100,0),0) -> 20
A10: 4759 | B10: 3274872441798 | C10: KENZO FLOWER L ABSOLUE EDP | D10: Kenzo | E10: Perfumería | F10: Fragancias | G10: Hombre | I10: KENZO FLOWER L ABSOLUE EDP | J10: Fragancia de la familia olfativa Oriental Floral . Se lanzó en 2022. La Nariz detrás de esta fragrancia es Alberto Morillas. Nota de Salida : azafrán; Notas de Corazón : rosa de Damasco y flor de azahar del naranjo; lNotas de Fondo : vainilla y almizcle blanco. Fragancia con intensidad y personalidad . | L10: NO | M10: SI | N10: 0 | R10: =IF(AND(P10>0,Q10>0),ROUND((1-Q10/P10)*100,0),0) -> 0
A11: 4760 | B11: 3274872480452 | C11: KENZO FLOWER CHERRY POPPY EDP | D11: Kenzo | E11: Perfumería | F11: Fragancias | G11: Hombre | I11: KENZO FLOWER CHERRY POPPY EDP | J11: Una cautivadora mezcla de deliciosos sabores. Su composición está inspirada en el arte de la repostería japonesa. Posee un carácter sutil, a la vez que distintivo y delicado: tierno y ácido, con una estética alegre y notas delicadamente equilibradas. Un deleite para los sentidos, FLOWER CHERRY POPPY reinventa la fragancia gourmet con un irresistible aroma floral afrutado. La frescura de la cereza negra, despierta el paladar. Un corazón floral, rebosante de feminidad, combina esencias de rosa damascena y nenúfar. El fondo es una reconfortante mezcla de suave almizcle blanco y esencia de cedro de Virginia. Una estela inusual y sutilmente suculenta. Una creación única de Dora Baghriche, quien domina el arte de expresar texturas y emociones olfativas, combinando sabores y aromas para deleitar los sentidos. El legendario frasco de FLOWER está adornado con la amapola rosa y violeta de KENZO, y su corazón es una tentadora explosión de cereza. Un nuevo tipo de placer olfativo, una delicia indescriptible. Familia Olfativa: Floral Afrutada. Notas de Salida: Cereza Negra. Notas de Fondo: Almizcles blancos. Notas de Corazón: Rosa Damascena y acorde de Nenúfar. | L11: NO | M11: SI | N11: 0 | R11: =IF(AND(P11>0,Q11>0),ROUND((1-Q11/P11)*100,0),0) -> 0
A12: 4761 | B12: 3274872427204 | C12: KENZO FLOWER EDP X 100 ml (RECARGABLE) | D12: Kenzo | E12: Perfumería | F12: Fragancias | G12: Hombre | I12: KENZO FLOWER EDP X 100 ml (RECARGABLE) | J12: Fragancia de la familia olfativa Oriental Floral . Se lanzó en 2000. Creada por Alberto Morillas y Christian Dussoulier. Perfume icónico de la Maison Kenzo. Imprevisible, la amapola crece allí donde no se la espera: seduce a la ciudad y a sus habitantes. KENZO inventa el perfume de esta flor, inodora por esencia;. Introducida por las bayas rosas, sostenida por la rosa búlgara, envueta por la vainilla y almizcles blancos, un eau de parfum sensual y envolvente converida en un icono de la perfumería. Reconocible entre todos, el frasco de Flower By Kenzo Eau de Parfum es depurado con líneas curvas que ilustran el poder de la flor que se abre camino entre los edificios. | L12: NO | M12: SI | N12: 0 | R12: =IF(AND(P12>0,Q12>0),ROUND((1-Q12/P12)*100,0),0) -> 0
A13: 4762 | B13: 3274872454590 | C13: KENZO FLOWER EDP X 100 + CREMA CUERPO + CREMA MANOS | D13: Kenzo | E13: Perfumería | F13: Fragancias | G13: Hombre | I13: KENZO FLOWER EDP X 100 + CREMA CUERPO + CREMA MANOS | L13: NO | M13: SI | N13: 0 | R13: =IF(AND(P13>0,Q13>0),ROUND((1-Q13/P13)*100,0),0) -> 0
A14: 4763 | B14: 3274872481336 | C14: KENZO FLOWER EDP X 100 + CREMA CUERPO + EDP | D14: Kenzo | E14: Perfumería | F14: Fragancias | G14: Hombre | I14: KENZO FLOWER EDP X 100 + CREMA CUERPO + EDP | L14: NO | M14: SI | N14: 0 | R14: =IF(AND(P14>0,Q14>0),ROUND((1-Q14/P14)*100,0),0) -> 0
A15: 4764 | B15: 3274872427211 | C15: KENZO FLOWER EDP X 200 ml TUBO RECARGA | D15: Kenzo | E15: Perfumería | F15: Fragancias | G15: Hombre | I15: KENZO FLOWER EDP X 200 ml TUBO RECARGA | L15: NO | M15: SI | N15: 0 | R15: =IF(AND(P15>0,Q15>0),ROUND((1-Q15/P15)*100,0),0) -> 0
A16: 4765 | B16: 3274872404175 | C16: KENZO FLOWER EDP | D16: Kenzo | E16: Perfumería | F16: Fragancias | G16: Hombre | I16: KENZO FLOWER EDP | L16: NO | M16: SI | N16: 0 | R16: =IF(AND(P16>0,Q16>0),ROUND((1-Q16/P16)*100,0),0) -> 0
A17: 4766 | B17: 3274872497733 | C17: KENZO FLOWER EDP X 50 ml + CREMA CUERPO + EDP | D17: Kenzo | E17: Perfumería | F17: Fragancias | G17: Hombre | I17: KENZO FLOWER EDP X 50 ml + CREMA CUERPO + EDP | L17: NO | M17: SI | N17: 0 | R17: =IF(AND(P17>0,Q17>0),ROUND((1-Q17/P17)*100,0),0) -> 0
A18: 4767 | B18: 3274872420359 | C18: KENZO FLOWER EDT | D18: Kenzo | E18: Perfumería | F18: Fragancias | G18: Hombre | I18: KENZO FLOWER EDT | J18: Fragancia de la familia olfativa Oriental Floral . Se lanzó en 2021. La Nariz detrás de esta fragrancia es Alberto Morillas. Notas de Salida : limón siciliano (lima siciliana), jengibre, mandarina y lichi; Notas de Corazón: manzanilla, rosa de Damasco, agua de rosas y mimosa; Notas de Fondo :son almizcle blanco, vainilla de Madagascar, ámbar y pachulí.Aroma fresco y agradable , muy femenino , | L18: NO | M18: SI | N18: 0 | R18: =IF(AND(P18>0,Q18>0),ROUND((1-Q18/P18)*100,0),0) -> 20
A19: 4768 | B19: 3274872469365 | C19: KENZO FLOWER IKEBANA MIMOSA EDP | D19: Kenzo | E19: Perfumería | F19: Fragancias | G19: Hombre | I19: KENZO FLOWER IKEBANA MIMOSA EDP | J19: Un homenaje al amor de Kenzo Takada por las flores y el arte de vivir. Sumergite en el cálido abrazo de un rayo de sol El nuevo ramo de sol floreciente. El absoluto de mimosa, en el corazón de la fragancia, ofrece una expresión aterciopelada y floral única. En las notas de fondo, la verticalidad de la madera de hinoki sostiene toda la composición, con extracto de sésamo dorado. Este Eau de Parfum, compuesto por un 91% de ingredientes de origen natural*, combina la más alta calidad de la mimosa con materias primas excepcionales. | L19: NO | M19: SI | N19: 0 | R19: =IF(AND(P19>0,Q19>0),ROUND((1-Q19/P19)*100,0),0) -> 0
A20: 4769 | B20: 3274872454460 | C20: KENZO FLOWER IKEBANA EDP | D20: Kenzo | E20: Perfumería | F20: Fragancias | G20: Hombre | I20: KENZO FLOWER IKEBANA EDP | J20: Un homenaje al amor de Kenzo Takada por las flores y por el arte de vivir. Una encrucijada de dos estéticas: la composición floral y la creatividad olfativa. La perfumista Alexandra Monet y el maestro perfumista Alberto Morillas han escrito este capítulo perfumado en la historia de Flower by Kenzo. Un equilibrio que descansa sobre tres notas: Té Sobacha con sus acentos tostados, delicada flor de Sakura realzado por el absoluto de nardo de la India y la preciada calidez de esencia de sándalo australiano. . Familia Olfativa: Floral Amaderada. Notas de fondo: Esencia de Sándalo Australiano, Esencia de Cedro y Esencia de Vetiver. Notas de corazón: Flor de Sakura y Absoluto de Tuberosa de la India Notas de salida: Té de Sobacha. | L20: NO | M20: SI | N20: 0 | R20: =IF(AND(P20>0,Q20>0),ROUND((1-Q20/P20)*100,0),0) -> 32
A21: 4770 | B21: 3274872464117 | C21: KENZO FLOWER IKEBANA EDP X 75 ml + EDP | D21: Kenzo | E21: Perfumería | F21: Fragancias | G21: Hombre | I21: KENZO FLOWER IKEBANA EDP X 75 ml + EDP | L21: NO | M21: SI | N21: 0 | R21: =IF(AND(P21>0,Q21>0),ROUND((1-Q21/P21)*100,0),0) -> 0
A22: 4771 | B22: 3274872467552 | C22: KENZO FLOWER IKEBANA EDP X 75 ml + CREMA CUERPO + EDP | D22: Kenzo | E22: Perfumería | F22: Fragancias | G22: Hombre | I22: KENZO FLOWER IKEBANA EDP X 75 ml + CREMA CUERPO + EDP | L22: NO | M22: SI | N22: 0 | R22: =IF(AND(P22>0,Q22>0),ROUND((1-Q22/P22)*100,0),0) -> 0
A23: 4772 | B23: 3274872480711 | C23: KENZO FLOWER IKEBANA INDIGO EDP | D23: Kenzo | E23: Perfumería | F23: Fragancias | G23: Hombre | I23: KENZO FLOWER IKEBANA INDIGO EDP | J23: Fragancia con una composicion floral ambarina realzada por ligeros tonos minerales. Kenzo rinde homenaje al color mas emblematico de Japon, el azul indigo, tambien conocido como azul japones, . Para este Eau de Parfum, los perfumistas Ane Ayo y Florian Gallo capturaron la esencia del azul japones utiizando Iris En el corazon de esta fragancia, el Iris, el oro azul de la perfumeria, despliega su poder olfativo a traves de notas empolvadas y amaderadas. En su base, un acorde mineral rico de tinta de Indigo se combina con matices ahumados de vainilla azul para crear una fragancia de sensualidad adictiva. | L23: NO | M23: SI | N23: 0 | R23: =IF(AND(P23>0,Q23>0),ROUND((1-Q23/P23)*100,0),0) -> 45
A24: 4773 | B24: 3274872477827 | C24: KENZO FLOWER LA RECOLTE PARISIENNE EDP | D24: Kenzo | E24: Perfumería | F24: Fragancias | G24: Hombre | I24: KENZO FLOWER LA RECOLTE PARISIENNE EDP | J24: Fragancia de la familia olfativa Floral . Se lanzó en 2024. Creada por Alberto Morillas y Dora Baghriche. Notas de Salida : pimienta rosa y mandarina amarilla; Notas de Corazón : dalia y rosa de Damasco; Notas de Fondo : almizcle blanco, haba tonka y vainilla.Un "abrazo " de notas florales ,muy parisino . | L24: NO | M24: SI | N24: 0 | R24: =IF(AND(P24>0,Q24>0),ROUND((1-Q24/P24)*100,0),0) -> 20
A25: 4774 | B25: 3274872423398 | C25: KENZO HOMME EDP | D25: Kenzo | E25: Perfumería | F25: Fragancias | G25: Hombre | I25: KENZO HOMME EDP | L25: NO | M25: SI | N25: 0 | R25: =IF(AND(P25>0,Q25>0),ROUND((1-Q25/P25)*100,0),0) -> 0
A26: 4775 | B26: 3274872421554 | C26: KENZO HOMME INTENSE EDT | D26: Kenzo | E26: Perfumería | F26: Fragancias | G26: Hombre | I26: KENZO HOMME INTENSE EDT | J26: Inspirada en la intensidad del bambú y la serenidad de la brisa marina. El perfumista Quentin Bisch está detrás de la KENZO HOMME Eau de Toilette Intense, amaderada y marina. La frescura de un acuerdo marino y las notas de cabeza del grano de pimienta rosa dejan paso a un acuerdo adictivo que combina la higuera y el sándalo, como la piel salada calentada por el sol. Un soplo de frescura amaderado y marino con alcohol natural. El diseño del nuevo frasco de KENZO HOMME Intense es la máxima representación de la verticalidad, que refleja la fuerza y flexibilidad del bambú. Su tapa biselada evoca el corte de una katana, una espada utilizada por los samuráis. | L26: NO | M26: SI | N26: 0 | R26: =IF(AND(P26>0,Q26>0),ROUND((1-Q26/P26)*100,0),0) -> 0
A27: 4776 | B27: 3274872464155 | C27: KENZO HOMME INTENSE EDT X 110 + GEL DUCHA + EDT | D27: Kenzo | E27: Perfumería | F27: Fragancias | G27: Hombre | I27: KENZO HOMME INTENSE EDT X 110 + GEL DUCHA + EDT | L27: NO | M27: SI | N27: 0 | R27: =IF(AND(P27>0,Q27>0),ROUND((1-Q27/P27)*100,0),0) -> 0
A28: 4777 | B28: 3274872476905 | C28: KENZO HOMME SANTAL MARINE EDT | D28: Kenzo | E28: Perfumería | F28: Fragancias | G28: Hombre | I28: KENZO HOMME SANTAL MARINE EDT | J28: Fragancia de la familia olfativa Amaderada Acuática .Se lanzó en 2024. La Nariz detrás de esta fragrancia es Quentin Bisch. Nota de Salida : notas marinas; Nota de Corazón : lavanda; Notas de Fondo :sándalo y madera de gaiac. | L28: NO | M28: SI | N28: 0 | R28: =IF(AND(P28>0,Q28>0),ROUND((1-Q28/P28)*100,0),0) -> 30
A29: 4778 | B29: 3274872289994 | C29: KENZO JUNGLE FEMME EDP | D29: Kenzo | E29: Perfumería | F29: Fragancias | G29: Hombre | I29: KENZO JUNGLE FEMME EDP | J29: Fragancia de la familia olfativa Oriental Especiada . Se lanzó en 1996. La Nariz detrás de esta fragrancia es Dominique Ropion. Notas de Salida :clavos de olor, comino y mandarina; Notas de Corazón :cardamomo, alcaravea, regaliz, mango, ylang-ylang, heliotropo y gardenia; Notas de Fondo : vainilla, ámbar y pachulí. | L29: NO | M29: SI | N29: 0 | R29: =IF(AND(P29>0,Q29>0),ROUND((1-Q29/P29)*100,0),0) -> 0
A30: 4779 | B30: 3274872444584 | C30: KENZO L EAU POUR HOMME EDT | D30: Kenzo | E30: Perfumería | F30: Fragancias | G30: Hombre | I30: KENZO L EAU POUR HOMME EDT | L30: NO | M30: SI | N30: 0 | R30: =IF(AND(P30>0,Q30>0),ROUND((1-Q30/P30)*100,0),0) -> 0
A31: 4780 | B31: 3274872505759 | C31: KENZO LE ROUGE FLOWER | D31: Kenzo | E31: Perfumería | F31: Fragancias | G31: Hombre | I31: KENZO LE ROUGE FLOWER | J31: Una fragancia floral gourmand que reinventa la icónica firma olfativa de FLOWER BY KENZO en una versión más intensa y sensual. Una intensidad envolvente Desde las primeras notas, los almizcles se abren con una sensación olfativa limpia. La rosa damascena aporta una nueva intensidad floral, mientras que Amberever®, la molécula amaderada más potente del mercado, junto con la vainilla y el sándalo, se fusionan para crear un confort cálido y gourmand. La inspiración Veinticinco años después del primer FLOWER BY KENZO, KENZO imagina a qué huele el rojo: LE ROUGE FLOWER captura toda la intensidad de un rojo profundo y vibrante que evoca las raíces de la Maison KENZO, Japón. Familia Olfativa:Floral Gourmand. Notas de Salida:Almizcles. Notas de Fondo:Amberever®, vainilla, sándalo. Notas de Corazón: Rosa damascena. | L31: NO | M31: SI | N31: 0 | R31: =IF(AND(P31>0,Q31>0),ROUND((1-Q31/P31)*100,0),0) -> 0
A32: 4781 | B32: 3274872497801 | C32: KENZO HOMME INTENSE EDT X 110 + GEL DUCHA + EDT INT | D32: Kenzo | E32: Perfumería | F32: Fragancias | G32: Hombre | I32: KENZO HOMME INTENSE EDT X 110 + GEL DUCHA + EDT INT | L32: NO | M32: SI | N32: 0 | R32: =IF(AND(P32>0,Q32>0),ROUND((1-Q32/P32)*100,0),0) -> 0
A33: 4782 | B33: 3274872423329 | C33: KENZO HOMME EDT | D33: Kenzo | E33: Perfumería | F33: Fragancias | G33: Hombre | I33: KENZO HOMME EDT | J33: Fragancia de la familia olfativa Amaderada Acuática .Se lanzó en 2022. Notas de Salida : notas marinas, Calipsone y nuez moscada; Notas de Corazón : pino y pachulí; Notas de Fondo ; sándalo y cedro. | L33: NO | M33: SI | N33: 0 | R33: =IF(AND(P33>0,Q33>0),ROUND((1-Q33/P33)*100,0),0) -> 37
A34: 4783 | B34: 3274872466982 | C34: KENZO HOMME EDT X 110 + GEL DUCHA + EDT | D34: Kenzo | E34: Perfumería | F34: Fragancias | G34: Hombre | I34: KENZO HOMME EDT X 110 + GEL DUCHA + EDT | L34: NO | M34: SI | N34: 0 | R34: =IF(AND(P34>0,Q34>0),ROUND((1-Q34/P34)*100,0),0) -> 0
A35: 4784 | B35: 3274872438088 | C35: KENZO HOMME MARINE EDT | D35: Kenzo | E35: Perfumería | F35: Fragancias | G35: Hombre | I35: KENZO HOMME MARINE EDT | J35: Fragancia de la familia olfativa Amaderada Acuática .Se lanzó en 2023. La Nariz detrás de esta fragrancia es Quentin Bisch. Nota de Salida : notas marinas; Nota de Corazón : ylang-ylang; Notas de Fondo : sándalo y almizcle. | L35: NO | M35: SI | N35: 0 | R35: =IF(AND(P35>0,Q35>0),ROUND((1-Q35/P35)*100,0),0) -> 30
A36: 4785 | B36: 3274872323483 | C36: KENZO WORLD EDP | D36: Kenzo | E36: Perfumería | F36: Fragancias | G36: Hombre | I36: KENZO WORLD EDP | J36: Descubre el mundo KENZO: audaz, espontáneo y sorprendente. Celebra la diversidad, la libertad de pensamiento y la expresión de uno mismo. Atrévete a ver el mundo a tu manera.Revisita el mundo de las flores y lo convierte en un perfume. Un encuentro inédito entre la peonía, el jazmín y los cristales resplandecientes de ambroxan®. | L36: NO | M36: SI | N36: 0 | R36: =IF(AND(P36>0,Q36>0),ROUND((1-Q36/P36)*100,0),0) -> 0
A37: 4786 | B37: 3274872440999 | C37: KENZO L EAU FEMME EDT X 100 ml ( RECARGABLE ) | D37: Kenzo | E37: Perfumería | F37: Fragancias | G37: Hombre | I37: KENZO L EAU FEMME EDT X 100 ml ( RECARGABLE ) | L37: NO | M37: SI | N37: 0 | R37: =IF(AND(P37>0,Q37>0),ROUND((1-Q37/P37)*100,0),0) -> 0
A38: 4787 | B38: 3274872390669 | C38: KENZO L EAU FEMME EDT | D38: Kenzo | E38: Perfumería | F38: Fragancias | G38: Hombre | I38: KENZO L EAU FEMME EDT | J38: Fagancia de la familia olfativa acuatica. Se lanzó en 1996. Nota de Salida : menta; Nota de Corazón : durazno (melocotón); Notas de Fondo : flor de loto y absoluto de vainilla. | L38: NO | M38: SI | N38: 0 | R38: =IF(AND(P38>0,Q38>0),ROUND((1-Q38/P38)*100,0),0) -> 0
A39: 4788 | B39: 3274872438422 | C39: KENZO L EAU FEMME FLORALE EDT | D39: Kenzo | E39: Perfumería | F39: Fragancias | G39: Hombre | I39: KENZO L EAU FEMME FLORALE EDT | J39: Familia olfativa Floral . Se lanzó en 2022. La Nariz detrás de esta fragrancia es Olivier Cresp. Nota de Salida : peonía; Nota de Corazón: rosa; Nota de Fondo : cedro. | L39: NO | M39: SI | N39: 0 | R39: =IF(AND(P39>0,Q39>0),ROUND((1-Q39/P39)*100,0),0) -> 30
A40: 4789 | B40: 3274872452503 | C40: KENZO L EAU FEMME SUNLIGHT EDT | D40: Kenzo | E40: Perfumería | F40: Fragancias | G40: Hombre | I40: KENZO L EAU FEMME SUNLIGHT EDT | J40: Fragancia de la familia olfativa Cítrica Aromática. Se lanzó en 2023. La Nariz detrás de esta fragrancia es Olivier Cresp. Notas de Salida : mandarina y notas acuáticas; Notas de Corazón : flor de loto y hoja de loto; Notas de Fondo : hojas de violeta y cedro. | L40: NO | M40: SI | N40: 0 | R40: =IF(AND(P40>0,Q40>0),ROUND((1-Q40/P40)*100,0),0) -> 30
...

Sheet 🔗 Variantes
A1: 🔗 MARYBE — Variantes exportadas
A2: ⚠ Una fila por variante. "producto_padre_id" debe coincidir con el "ID Original" de la hoja Productos. Columnas C e I son calculadas automáticamente.
A3: ID Variante * | B3: ID Producto Padre * | C3: Nombre Producto Padre 🔒 | D3: SKU / EAN | E3: Volumen / Tamaño | F3: Stock | G3: Precio * | H3: Precio Oferta | I3: % Descuento 🔒 | J3: Publicado | K3: Envío | L3: 🎨 Color
A4: 13900 | B4: 4752 | C4: =IF(B4<>"",IFERROR(VLOOKUP(B4,'📦 Productos'!A:C,3,FALSE),IFERROR(VLOOKUP(B4&"",'📦 Productos'!A:C,3,FALSE),IFERROR(VLOOKUP(VALUE(B4),'📦 Productos'!A:C,3,FALSE),""))),"") | D4: 3274872495852 | E4: 60 ml | F4: 0 | G4: 196000 | I4: =IF(AND(G4>0,H4>0),ROUND((1-H4/G4)*100,0),0) -> 0 | J4: SI | K4: 1
A5: 13901 | B5: 4752 | C5: =IF(B5<>"",IFERROR(VLOOKUP(B5,'📦 Productos'!A:C,3,FALSE),IFERROR(VLOOKUP(B5&"",'📦 Productos'!A:C,3,FALSE),IFERROR(VLOOKUP(VALUE(B5),'📦 Productos'!A:C,3,FALSE),""))),"") | D5: 3274872490529 | E5: 110 ml | F5: 0 | G5: 258000 | I5: =IF(AND(G5>0,H5>0),ROUND((1-H5/G5)*100,0),0) -> 0 | J5: SI | K5: 1
A6: 13905 | B6: 4754 | C6: =IF(B6<>"",IFERROR(VLOOKUP(B6,'📦 Productos'!A:C,3,FALSE),IFERROR(VLOOKUP(B6&"",'📦 Productos'!A:C,3,FALSE),IFERROR(VLOOKUP(VALUE(B6),'📦 Productos'!A:C,3,FALSE),""))),"") | D6: 3274872357129 | E6: 30 ml | F6: 0 | G6: 105000 | I6: =IF(AND(G6>0,H6>0),ROUND((1-H6/G6)*100,0),0) -> 0 | J6: SI | K6: 1
A7: 13906 | B7: 4754 | C7: =IF(B7<>"",IFERROR(VLOOKUP(B7,'📦 Productos'!A:C,3,FALSE),IFERROR(VLOOKUP(B7&"",'📦 Productos'!A:C,3,FALSE),IFERROR(VLOOKUP(VALUE(B7),'📦 Productos'!A:C,3,FALSE),""))),"") | D7: 3274872357143 | E7: 100 ml | F7: 0 | G7: 218000 | I7: =IF(AND(G7>0,H7>0),ROUND((1-H7/G7)*100,0),0) -> 0 | J7: SI | K7: 1
A8: 13907 | B8: 4754 | C8: =IF(B8<>"",IFERROR(VLOOKUP(B8,'📦 Productos'!A:C,3,FALSE),IFERROR(VLOOKUP(B8&"",'📦 Productos'!A:C,3,FALSE),IFERROR(VLOOKUP(VALUE(B8),'📦 Productos'!A:C,3,FALSE),""))),"") | D8: 3274872357136 | E8: 50 ml | F8: 0 | G8: 150000 | I8: =IF(AND(G8>0,H8>0),ROUND((1-H8/G8)*100,0),0) -> 0 | J8: SI | K8: 1
A9: 13908 | B9: 4755 | C9: =IF(B9<>"",IFERROR(VLOOKUP(B9,'📦 Productos'!A:C,3,FALSE),IFERROR(VLOOKUP(B9&"",'📦 Productos'!A:C,3,FALSE),IFERROR(VLOOKUP(VALUE(B9),'📦 Productos'!A:C,3,FALSE),""))),"") | D9: 3274872357228 | E9: 100 ml | F9: 0 | G9: 218000 | I9: =IF(AND(G9>0,H9>0),ROUND((1-H9/G9)*100,0),0) -> 0 | J9: SI | K9: 1
A10: 13909 | B10: 4755 | C10: =IF(B10<>"",IFERROR(VLOOKUP(B10,'📦 Productos'!A:C,3,FALSE),IFERROR(VLOOKUP(B10&"",'📦 Productos'!A:C,3,FALSE),IFERROR(VLOOKUP(VALUE(B10),'📦 Productos'!A:C,3,FALSE),""))),"") | D10: 3274872357204 | E10: 30 ml | F10: 0 | G10: 105000 | I10: =IF(AND(G10>0,H10>0),ROUND((1-H10/G10)*100,0),0) -> 0 | J10: SI | K10: 1
A11: 13910 | B11: 4755 | C11: =IF(B11<>"",IFERROR(VLOOKUP(B11,'📦 Productos'!A:C,3,FALSE),IFERROR(VLOOKUP(B11&"",'📦 Productos'!A:C,3,FALSE),IFERROR(VLOOKUP(VALUE(B11),'📦 Productos'!A:C,3,FALSE),""))),"") | D11: 3274872357211 | E11: 50 ml | F11: 0 | G11: 150000 | I11: =IF(AND(G11>0,H11>0),ROUND((1-H11/G11)*100,0),0) -> 0 | J11: SI | K11: 1
A12: 13911 | B12: 4756 | C12: =IF(B12<>"",IFERROR(VLOOKUP(B12,'📦 Productos'!A:C,3,FALSE),IFERROR(VLOOKUP(B12&"",'📦 Productos'!A:C,3,FALSE),IFERROR(VLOOKUP(VALUE(B12),'📦 Productos'!A:C,3,FALSE),""))),"") | D12: 3274872430587 | E12: 75 | F12: 0 | G12: 268000 | H12: 166160 | I12: =IF(AND(G12>0,H12>0),ROUND((1-H12/G12)*100,0),0) -> 38 | J12: SI | K12: 1
A13: 13912 | B13: 4757 | C13: =IF(B13<>"",IFERROR(VLOOKUP(B13,'📦 Productos'!A:C,3,FALSE),IFERROR(VLOOKUP(B13&"",'📦 Productos'!A:C,3,FALSE),IFERROR(VLOOKUP(VALUE(B13),'📦 Productos'!A:C,3,FALSE),""))),"") | D13: 3274872406216 | E13: 100 ml | F13: 0 | G13: 301000 | I13: =IF(AND(G13>0,H13>0),ROUND((1-H13/G13)*100,0),0) -> 0 | J13: SI | K13: 1
A14: 13913 | B14: 4757 | C14: =IF(B14<>"",IFERROR(VLOOKUP(B14,'📦 Productos'!A:C,3,FALSE),IFERROR(VLOOKUP(B14&"",'📦 Productos'!A:C,3,FALSE),IFERROR(VLOOKUP(VALUE(B14),'📦 Productos'!A:C,3,FALSE),""))),"") | D14: 3274872406193 | E14: 30 ml | F14: 0 | G14: 162000 | I14: =IF(AND(G14>0,H14>0),ROUND((1-H14/G14)*100,0),0) -> 0 | J14: SI | K14: 1
A15: 13914 | B15: 4757 | C15: =IF(B15<>"",IFERROR(VLOOKUP(B15,'📦 Productos'!A:C,3,FALSE),IFERROR(VLOOKUP(B15&"",'📦 Productos'!A:C,3,FALSE),IFERROR(VLOOKUP(VALUE(B15),'📦 Productos'!A:C,3,FALSE),""))),"") | D15: 3274872406209 | E15: 50 ml | F15: 0 | G15: 231000 | I15: =IF(AND(G15>0,H15>0),ROUND((1-H15/G15)*100,0),0) -> 0 | J15: SI | K15: 1
A16: 13915 | B16: 4757 | C16: =IF(B16<>"",IFERROR(VLOOKUP(B16,'📦 Productos'!A:C,3,FALSE),IFERROR(VLOOKUP(B16&"",'📦 Productos'!A:C,3,FALSE),IFERROR(VLOOKUP(VALUE(B16),'📦 Productos'!A:C,3,FALSE),""))),"") | D16: 3274872462281 | E16: 30 ml | F16: 0 | G16: 162000 | H16: 119880 | I16: =IF(AND(G16>0,H16>0),ROUND((1-H16/G16)*100,0),0) -> 26 | J16: SI | K16: 1
A17: 13916 | B17: 4757 | C17: =IF(B17<>"",IFERROR(VLOOKUP(B17,'📦 Productos'!A:C,3,FALSE),IFERROR(VLOOKUP(B17&"",'📦 Productos'!A:C,3,FALSE),IFERROR(VLOOKUP(VALUE(B17),'📦 Productos'!A:C,3,FALSE),""))),"") | D17: 3274872462298 | E17: 50 ml | F17: 0 | G17: 231000 | I17: =IF(AND(G17>0,H17>0),ROUND((1-H17/G17)*100,0),0) -> 0 | J17: SI | K17: 1
A18: 13917 | B18: 4758 | C18: =IF(B18<>"",IFERROR(VLOOKUP(B18,'📦 Productos'!A:C,3,FALSE),IFERROR(VLOOKUP(B18&"",'📦 Productos'!A:C,3,FALSE),IFERROR(VLOOKUP(VALUE(B18),'📦 Productos'!A:C,3,FALSE),""))),"") | D18: 3274872439603 | E18: 50 ml | F18: 0 | G18: 151500 | H18: 121200 | I18: =IF(AND(G18>0,H18>0),ROUND((1-H18/G18)*100,0),0) -> 20 | J18: SI | K18: 1
A19: 13918 | B19: 4759 | C19: =IF(B19<>"",IFERROR(VLOOKUP(B19,'📦 Productos'!A:C,3,FALSE),IFERROR(VLOOKUP(B19&"",'📦 Productos'!A:C,3,FALSE),IFERROR(VLOOKUP(VALUE(B19),'📦 Productos'!A:C,3,FALSE),""))),"") | D19: 3274872441798 | E19: 100 ml | F19: 0 | G19: 247700 | I19: =IF(AND(G19>0,H19>0),ROUND((1-H19/G19)*100,0),0) -> 0 | J19: SI | K19: 1
A20: 13919 | B20: 4759 | C20: =IF(B20<>"",IFERROR(VLOOKUP(B20,'📦 Productos'!A:C,3,FALSE),IFERROR(VLOOKUP(B20&"",'📦 Productos'!A:C,3,FALSE),IFERROR(VLOOKUP(VALUE(B20),'📦 Productos'!A:C,3,FALSE),""))),"") | D20: 3274872441774 | E20: 30 ml | F20: 0 | G20: 141000 | I20: =IF(AND(G20>0,H20>0),ROUND((1-H20/G20)*100,0),0) -> 0 | J20: SI | K20: 1
A21: 13920 | B21: 4759 | C21: =IF(B21<>"",IFERROR(VLOOKUP(B21,'📦 Productos'!A:C,3,FALSE),IFERROR(VLOOKUP(B21&"",'📦 Productos'!A:C,3,FALSE),IFERROR(VLOOKUP(VALUE(B21),'📦 Productos'!A:C,3,FALSE),""))),"") | D21: 3274872441781 | E21: 50 ml | F21: 0 | G21: 196400 | I21: =IF(AND(G21>0,H21>0),ROUND((1-H21/G21)*100,0),0) -> 0 | J21: SI | K21: 1
A22: 13921 | B22: 4760 | C22: =IF(B22<>"",IFERROR(VLOOKUP(B22,'📦 Productos'!A:C,3,FALSE),IFERROR(VLOOKUP(B22&"",'📦 Productos'!A:C,3,FALSE),IFERROR(VLOOKUP(VALUE(B22),'📦 Productos'!A:C,3,FALSE),""))),"") | D22: 3274872480452 | E22: 100 ml | F22: 0 | G22: 240000 | I22: =IF(AND(G22>0,H22>0),ROUND((1-H22/G22)*100,0),0) -> 0 | J22: SI | K22: 1
A23: 13922 | B23: 4760 | C23: =IF(B23<>"",IFERROR(VLOOKUP(B23,'📦 Productos'!A:C,3,FALSE),IFERROR(VLOOKUP(B23&"",'📦 Productos'!A:C,3,FALSE),IFERROR(VLOOKUP(VALUE(B23),'📦 Productos'!A:C,3,FALSE),""))),"") | D23: 3274872480476 | E23: 30 ml | F23: 0 | G23: 130000 | I23: =IF(AND(G23>0,H23>0),ROUND((1-H23/G23)*100,0),0) -> 0 | J23: SI | K23: 1
A24: 13923 | B24: 4760 | C24: =IF(B24<>"",IFERROR(VLOOKUP(B24,'📦 Productos'!A:C,3,FALSE),IFERROR(VLOOKUP(B24&"",'📦 Productos'!A:C,3,FALSE),IFERROR(VLOOKUP(VALUE(B24),'📦 Productos'!A:C,3,FALSE),""))),"") | D24: 3274872480469 | E24: 50 ml | F24: 0 | G24: 183000 | I24: =IF(AND(G24>0,H24>0),ROUND((1-H24/G24)*100,0),0) -> 0 | J24: SI | K24: 1
A25: 13924 | B25: 4761 | C25: =IF(B25<>"",IFERROR(VLOOKUP(B25,'📦 Productos'!A:C,3,FALSE),IFERROR(VLOOKUP(B25&"",'📦 Productos'!A:C,3,FALSE),IFERROR(VLOOKUP(VALUE(B25),'📦 Productos'!A:C,3,FALSE),""))),"") | D25: 3274872427204 | F25: 0 | G25: 299000 | I25: =IF(AND(G25>0,H25>0),ROUND((1-H25/G25)*100,0),0) -> 0 | J25: SI | K25: 1
A26: 13925 | B26: 4762 | C26: =IF(B26<>"",IFERROR(VLOOKUP(B26,'📦 Productos'!A:C,3,FALSE),IFERROR(VLOOKUP(B26&"",'📦 Productos'!A:C,3,FALSE),IFERROR(VLOOKUP(VALUE(B26),'📦 Productos'!A:C,3,FALSE),""))),"") | D26: 3274872454590 | F26: 0 | G26: 299000 | I26: =IF(AND(G26>0,H26>0),ROUND((1-H26/G26)*100,0),0) -> 0 | J26: SI | K26: 1
A27: 13926 | B27: 4763 | C27: =IF(B27<>"",IFERROR(VLOOKUP(B27,'📦 Productos'!A:C,3,FALSE),IFERROR(VLOOKUP(B27&"",'📦 Productos'!A:C,3,FALSE),IFERROR(VLOOKUP(VALUE(B27),'📦 Productos'!A:C,3,FALSE),""))),"") | D27: 3274872481336 | E27: 10 ml | F27: 0 | G27: 299000 | I27: =IF(AND(G27>0,H27>0),ROUND((1-H27/G27)*100,0),0) -> 0 | J27: SI | K27: 1
A28: 13927 | B28: 4764 | C28: =IF(B28<>"",IFERROR(VLOOKUP(B28,'📦 Productos'!A:C,3,FALSE),IFERROR(VLOOKUP(B28&"",'📦 Productos'!A:C,3,FALSE),IFERROR(VLOOKUP(VALUE(B28),'📦 Productos'!A:C,3,FALSE),""))),"") | D28: 3274872427211 | F28: 0 | G28: 315000 | I28: =IF(AND(G28>0,H28>0),ROUND((1-H28/G28)*100,0),0) -> 0 | J28: SI | K28: 1
A29: 13928 | B29: 4765 | C29: =IF(B29<>"",IFERROR(VLOOKUP(B29,'📦 Productos'!A:C,3,FALSE),IFERROR(VLOOKUP(B29&"",'📦 Productos'!A:C,3,FALSE),IFERROR(VLOOKUP(VALUE(B29),'📦 Productos'!A:C,3,FALSE),""))),"") | D29: 3274872404175 | E29: 50 ml | F29: 0 | G29: 230000 | I29: =IF(AND(G29>0,H29>0),ROUND((1-H29/G29)*100,0),0) -> 0 | J29: SI | K29: 1
A30: 13929 | B30: 4765 | C30: =IF(B30<>"",IFERROR(VLOOKUP(B30,'📦 Productos'!A:C,3,FALSE),IFERROR(VLOOKUP(B30&"",'📦 Productos'!A:C,3,FALSE),IFERROR(VLOOKUP(VALUE(B30),'📦 Productos'!A:C,3,FALSE),""))),"") | D30: 3274872404113 | E30: 30 ml | F30: 0 | G30: 162000 | I30: =IF(AND(G30>0,H30>0),ROUND((1-H30/G30)*100,0),0) -> 0 | J30: SI | K30: 1
A31: 13930 | B31: 4766 | C31: =IF(B31<>"",IFERROR(VLOOKUP(B31,'📦 Productos'!A:C,3,FALSE),IFERROR(VLOOKUP(B31&"",'📦 Productos'!A:C,3,FALSE),IFERROR(VLOOKUP(VALUE(B31),'📦 Productos'!A:C,3,FALSE),""))),"") | D31: 3274872497733 | E31: 10 ml | F31: 0 | G31: 230000 | I31: =IF(AND(G31>0,H31>0),ROUND((1-H31/G31)*100,0),0) -> 0 | J31: SI | K31: 1
A32: 13931 | B32: 4767 | C32: =IF(B32<>"",IFERROR(VLOOKUP(B32,'📦 Productos'!A:C,3,FALSE),IFERROR(VLOOKUP(B32&"",'📦 Productos'!A:C,3,FALSE),IFERROR(VLOOKUP(VALUE(B32),'📦 Productos'!A:C,3,FALSE),""))),"") | D32: 3274872420359 | E32: 100 ml | F32: 0 | G32: 194500 | H32: 155600 | I32: =IF(AND(G32>0,H32>0),ROUND((1-H32/G32)*100,0),0) -> 20 | J32: SI | K32: 1
A33: 13932 | B33: 4767 | C33: =IF(B33<>"",IFERROR(VLOOKUP(B33,'📦 Productos'!A:C,3,FALSE),IFERROR(VLOOKUP(B33&"",'📦 Productos'!A:C,3,FALSE),IFERROR(VLOOKUP(VALUE(B33),'📦 Productos'!A:C,3,FALSE),""))),"") | D33: 3274872420342 | E33: 50 ml | F33: 0 | G33: 151500 | H33: 121200 | I33: =IF(AND(G33>0,H33>0),ROUND((1-H33/G33)*100,0),0) -> 20 | J33: SI | K33: 1
A34: 13933 | B34: 4768 | C34: =IF(B34<>"",IFERROR(VLOOKUP(B34,'📦 Productos'!A:C,3,FALSE),IFERROR(VLOOKUP(B34&"",'📦 Productos'!A:C,3,FALSE),IFERROR(VLOOKUP(VALUE(B34),'📦 Productos'!A:C,3,FALSE),""))),"") | D34: 3274872469365 | E34: 40 ml | F34: 0 | G34: 210000 | I34: =IF(AND(G34>0,H34>0),ROUND((1-H34/G34)*100,0),0) -> 0 | J34: SI | K34: 1
A35: 13934 | B35: 4768 | C35: =IF(B35<>"",IFERROR(VLOOKUP(B35,'📦 Productos'!A:C,3,FALSE),IFERROR(VLOOKUP(B35&"",'📦 Productos'!A:C,3,FALSE),IFERROR(VLOOKUP(VALUE(B35),'📦 Productos'!A:C,3,FALSE),""))),"") | D35: 3274872469372 | E35: 75 ml | F35: 0 | G35: 257000 | I35: =IF(AND(G35>0,H35>0),ROUND((1-H35/G35)*100,0),0) -> 0 | J35: SI | K35: 1
A36: 13935 | B36: 4769 | C36: =IF(B36<>"",IFERROR(VLOOKUP(B36,'📦 Productos'!A:C,3,FALSE),IFERROR(VLOOKUP(B36&"",'📦 Productos'!A:C,3,FALSE),IFERROR(VLOOKUP(VALUE(B36),'📦 Productos'!A:C,3,FALSE),""))),"") | D36: 3274872454460 | E36: 40 ml | F36: 0 | G36: 210000 | H36: 144900 | I36: =IF(AND(G36>0,H36>0),ROUND((1-H36/G36)*100,0),0) -> 31 | J36: SI | K36: 1
A37: 13936 | B37: 4769 | C37: =IF(B37<>"",IFERROR(VLOOKUP(B37,'📦 Productos'!A:C,3,FALSE),IFERROR(VLOOKUP(B37&"",'📦 Productos'!A:C,3,FALSE),IFERROR(VLOOKUP(VALUE(B37),'📦 Productos'!A:C,3,FALSE),""))),"") | D37: 3274872454477 | E37: 75 ml | F37: 0 | G37: 257000 | H37: 174760 | I37: =IF(AND(G37>0,H37>0),ROUND((1-H37/G37)*100,0),0) -> 32 | J37: SI | K37: 1
A38: 13937 | B38: 4770 | C38: =IF(B38<>"",IFERROR(VLOOKUP(B38,'📦 Productos'!A:C,3,FALSE),IFERROR(VLOOKUP(B38&"",'📦 Productos'!A:C,3,FALSE),IFERROR(VLOOKUP(VALUE(B38),'📦 Productos'!A:C,3,FALSE),""))),"") | D38: 3274872464117 | E38: 10 ml | F38: 0 | G38: 257000 | I38: =IF(AND(G38>0,H38>0),ROUND((1-H38/G38)*100,0),0) -> 0 | J38: SI | K38: 1
A39: 13938 | B39: 4771 | C39: =IF(B39<>"",IFERROR(VLOOKUP(B39,'📦 Productos'!A:C,3,FALSE),IFERROR(VLOOKUP(B39&"",'📦 Productos'!A:C,3,FALSE),IFERROR(VLOOKUP(VALUE(B39),'📦 Productos'!A:C,3,FALSE),""))),"") | D39: 3274872467552 | E39: 10 ml | F39: 0 | G39: 257000 | I39: =IF(AND(G39>0,H39>0),ROUND((1-H39/G39)*100,0),0) -> 0 | J39: SI | K39: 1
A40: 13939 | B40: 4772 | C40: =IF(B40<>"",IFERROR(VLOOKUP(B40,'📦 Productos'!A:C,3,FALSE),IFERROR(VLOOKUP(B40&"",'📦 Productos'!A:C,3,FALSE),IFERROR(VLOOKUP(VALUE(B40),'📦 Productos'!A:C,3,FALSE),""))),"") | D40: 3274872480711 | E40: 40 ml | F40: 0 | G40: 210000 | H40: 117600 | I40: =IF(AND(G40>0,H40>0),ROUND((1-H40/G40)*100,0),0) -> 44 | J40: SI | K40: 1
...

Sheet Listas
A1: _SECCIONES | B1: _CATEGORIAS | C1: _SUBCATEGORIAS | D1: _TIPOS | E1: _COLORES | F1: _BOOLEANOS
A2: Perfumería | B2: Ofertas | C2: Fragancias | D2: Limpieza facial | E2: Blanco | F2: SI
A3: Hogar | B3: Dermocosmetica | C3: Maquillaje | D3: Exfoliantes y Mascarillas | E3: Negro | F3: NO
B4: Fragancias | C4: Dermocosmetica | D4: Tónicos | E4: Gris
B5: Maquillaje | C5: Cuidado Personal | D5: Cremas Faciales | E5: Rojo
B6: Cuidado Personal | C6: Bebés y niños | D6: Serums | E6: Rosa
B7: Niños y BebÉs | C7: Limpieza del hogar | D7: Contornos de ojos y labios | E7: Fucsia
B8: Limpieza del hogar | C8: Cuidado facial | D8: Accesorios | E8: Nude
B9: Electro belleza | C9: Cuidado Corporal | D9: Cremas Corporales | E9: Beige
B10: Lanzamientos | C10: Solares | D10: Cremas de manos | E10: Marrón
C11: Femeninas | D11: Cremas para masajes | E11: Azul
C12: Masculinos | D12: Exfoliantes | E12: Celeste
C13: Labios | D13: Faciales | E13: Verde
C14: Ojos | D14: Corporales | E14: Amarillo
C15: Rostro | D15: Autobronceantes | E15: Naranja
C16: Uñas | D16: Post Solares | E16: Violeta
C17: Accesorios | D17: Premium | E17: Lila
C18: Cuidado Capilar | D18: Sets | E18: Dorado
C19: Higiene Corporal | D19: Semi selectivos | E19: Plateado
C20: Higiene Oral | D20: Nacionales | E20: Cobre
C21: Cuidado Intimo | D21: Body Splash y Colonias | E21: Transparente
C22: Pañales | D22: Labiales Liquidos
C23: Higiene del Bebe | D23: Labiales en Barra
C24: Jabones | D24: Bálsamos Labiales
C25: Colonias | D25: Brillos Labiales
C26: Desodorantes | D26: Delineadores
C27: Cuidado materno | D27: Mascaras de pestañas
C28: Cremas y cepillos dentales | D28: Sombras
C29: Capilares | D29: Delineadores en Lapiz
C30: Cocina | D30: Delineadores Liquidos
C31: Baño | D31: Cejas
C32: Pisos y Muebles | D32: Bases de Maquillaje
C33: Insecticida y Repelentes | D33: Correctores de Ojeras
... C44: Cabinas y Tornos de Uñas | D44: Esponjas
D45: Shampoo
D46: Acondicionadores
D47: Tratamientos Capilares
D48: Coloración
D49: Gel y Fijadores
D50: Cepillos y Peines
...
